2019-02-26 15:43:00,280 - INFO - Бот запускается
2019-02-26 15:43:14,766 - INFO - User: Myasni, Chat id: 247451475, Message: \start
2019-02-26 15:43:27,396 - INFO - User: Myasni, Chat id: 247451475, Message: \planet
2019-02-26 15:43:37,724 - INFO - Received signal 2 (SIGINT), stopping...
2019-02-26 15:45:03,670 - INFO - Бот запускается
2019-02-26 15:45:06,891 - ERROR - An uncaught error was raised while processing the update
Traceback (most recent call last):
  File "/anaconda3/lib/python3.6/site-packages/telegram/ext/dispatcher.py", line 279, in process_update
    handler.handle_update(update, self)
  File "/anaconda3/lib/python3.6/site-packages/telegram/ext/commandhandler.py", line 173, in handle_update
    return self.callback(dispatcher.bot, update, **optional_args)
TypeError: get_constellation() takes 1 positional argument but 2 were given
2019-02-26 15:45:06,900 - ERROR - An uncaught error was raised while processing the update
Traceback (most recent call last):
  File "/anaconda3/lib/python3.6/site-packages/telegram/ext/dispatcher.py", line 279, in process_update
    handler.handle_update(update, self)
  File "/anaconda3/lib/python3.6/site-packages/telegram/ext/commandhandler.py", line 173, in handle_update
    return self.callback(dispatcher.bot, update, **optional_args)
TypeError: get_constellation() takes 1 positional argument but 2 were given
2019-02-26 15:45:16,391 - ERROR - An uncaught error was raised while processing the update
Traceback (most recent call last):
  File "/anaconda3/lib/python3.6/site-packages/telegram/ext/dispatcher.py", line 279, in process_update
    handler.handle_update(update, self)
  File "/anaconda3/lib/python3.6/site-packages/telegram/ext/commandhandler.py", line 173, in handle_update
    return self.callback(dispatcher.bot, update, **optional_args)
TypeError: get_constellation() takes 1 positional argument but 2 were given
2019-02-26 15:45:53,548 - INFO - Received signal 2 (SIGINT), stopping...
2019-02-26 15:45:54,024 - WARNING - Exiting immediately!
2019-02-26 15:45:56,710 - INFO - Бот запускается
2019-02-26 15:48:31,898 - INFO - Received signal 2 (SIGINT), stopping...
2019-02-26 15:49:34,030 - INFO - Бот запускается
2019-02-26 15:49:53,678 - INFO - Received signal 2 (SIGINT), stopping...
2019-02-26 15:51:02,110 - INFO - Бот запускается
2019-02-26 15:51:27,897 - INFO - Received signal 2 (SIGINT), stopping...
2019-02-26 21:29:24,757 - INFO - Бот запускается
2019-02-26 21:29:43,884 - ERROR - An uncaught error was raised while processing the update
Traceback (most recent call last):
  File "/anaconda3/lib/python3.6/site-packages/telegram/ext/dispatcher.py", line 279, in process_update
    handler.handle_update(update, self)
  File "/anaconda3/lib/python3.6/site-packages/telegram/ext/commandhandler.py", line 173, in handle_update
    return self.callback(dispatcher.bot, update, **optional_args)
  File "bot.py", line 19, in get_constellation
    planet = update.message.text.split()[1]
IndexError: list index out of range
2019-02-26 21:29:56,582 - ERROR - An uncaught error was raised while processing the update
Traceback (most recent call last):
  File "/anaconda3/lib/python3.6/site-packages/telegram/ext/dispatcher.py", line 279, in process_update
    handler.handle_update(update, self)
  File "/anaconda3/lib/python3.6/site-packages/telegram/ext/commandhandler.py", line 173, in handle_update
    return self.callback(dispatcher.bot, update, **optional_args)
  File "bot.py", line 23, in get_constellation
    planet_ephem.compute(now)
NameError: name 'now' is not defined
2019-02-26 21:32:05,276 - INFO - Received signal 2 (SIGINT), stopping...
2019-02-26 21:32:10,250 - INFO - Бот запускается
2019-02-26 21:32:21,072 - ERROR - An uncaught error was raised while processing the update
Traceback (most recent call last):
  File "/anaconda3/lib/python3.6/site-packages/telegram/ext/dispatcher.py", line 279, in process_update
    handler.handle_update(update, self)
  File "/anaconda3/lib/python3.6/site-packages/telegram/ext/commandhandler.py", line 173, in handle_update
    return self.callback(dispatcher.bot, update, **optional_args)
  File "bot.py", line 19, in get_constellation
    planet = update.message.text.split()[1]
IndexError: list index out of range
2019-02-26 21:33:44,867 - INFO - Received signal 2 (SIGINT), stopping...
2019-02-26 21:33:48,800 - INFO - Бот запускается
2019-02-26 21:33:58,971 - ERROR - An uncaught error was raised while processing the update
Traceback (most recent call last):
  File "/anaconda3/lib/python3.6/site-packages/telegram/ext/dispatcher.py", line 279, in process_update
    handler.handle_update(update, self)
  File "/anaconda3/lib/python3.6/site-packages/telegram/ext/commandhandler.py", line 173, in handle_update
    return self.callback(dispatcher.bot, update, **optional_args)
  File "bot.py", line 19, in get_constellation
    planet = update.message.text.split()[1]
IndexError: list index out of range
2019-02-26 21:36:02,261 - INFO - User: Myasni, Chat id: 247451475, Message: planet f
2019-02-26 21:36:06,505 - INFO - User: Myasni, Chat id: 247451475, Message: Hyperion
2019-02-26 21:36:19,054 - ERROR - An uncaught error was raised while processing the update
Traceback (most recent call last):
  File "/anaconda3/lib/python3.6/site-packages/telegram/ext/dispatcher.py", line 279, in process_update
    handler.handle_update(update, self)
  File "/anaconda3/lib/python3.6/site-packages/telegram/ext/commandhandler.py", line 173, in handle_update
    return self.callback(dispatcher.bot, update, **optional_args)
  File "bot.py", line 24, in get_constellation
    update.message.reply_text(f'Созвездия:{ephem.constellation(planet_ephem)}')
TypeError: you must specify a position by providing either a body or a sequence of two numeric coordinates
2019-02-26 21:40:38,626 - INFO - Received signal 2 (SIGINT), stopping...
